Traceback (most recent call last):
  File "main.py", line 98, in <module>
    main()
  File "main.py", line 47, in main
    cf.resize_image_valid, cf.valid_batch_size)
  File "/home/grupo03/M5/Code/dataloader/dataloader_builder.py", line 61, in build_valid
    valid=True)
  File "/home/grupo03/M5/Code/dataloader/fromFileDatasetSegmentation.py", line 17, in __init__
    with open(image_txt) as f:
IOError: [Errno 2] No such file or directory: '/home/grupo03/M5/Code/city_txt_seg/val_images.txt'
