/home/grupo03/M5/Code/models/networks/segmentation/UNet.py:86: UserWarning: nn.init.kaiming_normal is now deprecated in favor of nn.init.kaiming_normal_.
  nn.init.kaiming_normal(module.weight)
/home/grupo03/.local/lib/python2.7/site-packages/skimage/transform/_warps.py:110: UserWarning: Anti-aliasing will be enabled by default in skimage 0.15 to avoid aliasing artifacts when down-sampling images.
  warn("Anti-aliasing will be enabled by default in skimage 0.15 to "
/home/grupo03/.local/lib/python2.7/site-packages/skimage/transform/_warps.py:110: UserWarning: Anti-aliasing will be enabled by default in skimage 0.15 to avoid aliasing artifacts when down-sampling images.
  warn("Anti-aliasing will be enabled by default in skimage 0.15 to "
/home/grupo03/.local/lib/python2.7/site-packages/skimage/transform/_warps.py:110: UserWarning: Anti-aliasing will be enabled by default in skimage 0.15 to avoid aliasing artifacts when down-sampling images.
  warn("Anti-aliasing will be enabled by default in skimage 0.15 to "
/home/grupo03/.local/lib/python2.7/site-packages/skimage/transform/_warps.py:110: UserWarning: Anti-aliasing will be enabled by default in skimage 0.15 to avoid aliasing artifacts when down-sampling images.
  warn("Anti-aliasing will be enabled by default in skimage 0.15 to "
Traceback (most recent call last):
  File "main.py", line 98, in <module>
    main()
  File "main.py", line 49, in main
    dataloader.loader_set, dataloader.loader)
  File "/home/grupo03/M5/Code/tasks/simple_trainer_manager.py", line 85, in start
    self.training_loop(epoch, train_loader, epoch_bar)
  File "/home/grupo03/M5/Code/tasks/simple_trainer_manager.py", line 118, in training_loop
    for i, data in enumerate(train_loader):
  File "/home/grupo03/anaconda3/lib/python2.7/site-packages/torch/utils/data/dataloader.py", line 336, in __next__
    return self._process_next_batch(batch)
  File "/home/grupo03/anaconda3/lib/python2.7/site-packages/torch/utils/data/dataloader.py", line 357, in _process_next_batch
    raise batch.exc_type(batch.exc_msg)
IOError: Traceback (most recent call last):
  File "/home/grupo03/anaconda3/lib/python2.7/site-packages/torch/utils/data/dataloader.py", line 106, in _worker_loop
    samples = collate_fn([dataset[i] for i in batch_indices])
  File "/home/grupo03/M5/Code/dataloader/fromFileDatasetSegmentation.py", line 41, in __getitem__
    gt, _ = self.cf.map_labels[self.load_img(gt_path, self.resize, grayscale=True, order=0)]
  File "/home/grupo03/M5/Code/dataloader/dataloader.py", line 72, in load_img
    img = io.imread(path)
  File "/home/grupo03/.local/lib/python2.7/site-packages/skimage/io/_io.py", line 62, in imread
    img = call_plugin('imread', fname, plugin=plugin, **plugin_args)
  File "/home/grupo03/.local/lib/python2.7/site-packages/skimage/io/manage_plugins.py", line 214, in call_plugin
    return func(*args, **kwargs)
  File "/home/grupo03/.local/lib/python2.7/site-packages/skimage/io/_plugins/pil_plugin.py", line 35, in imread
    with open(fname, 'rb') as f:
IOError: [Errno 2] No such file or directory: 'p3'

